# 异常处理

- 异常提供了一种将控制权从程序的一部分转移到另一部分的方法。C ++异常处理基于三个关键字构建：**try，catch**和**throw**。
  - `throw`:当出现问题时，程序抛出异常。这是使用一个`throw`关键字完成的。
  - `catch`:程序在程序中希望处理问题的位置使用异常处理程序捕获异常。`catch`关键字指示捕获异常。
  - `try`:一个`try`块标识将为其激活特定异常的代码块。后面跟着一个或多个`catch`块。



```c++
try{
    // protected code
}catch(exception_name e1){
    // catch block
}catch(exception_name e2){
    // catch block
}catch(exception_name eN){
    // catch block
}
```



****

## 抛出异常

- 可以使用`throw*`语句在代码块内的任何位置抛出异常 。`throw`语句的操作数确定异常的类型，可以是任何表达式，表达式结果的类型确定抛出的异常的类型。



****

## 捕捉异常

- `try`块后面的`catch`块捕获任何异常。您可以指定想要捕获的异常类型，这由关键字`catch`后面的括号中的异常声明确定。



```c++
try{
    // protected code
}catch(exception_name e){
	// code to handle exception_name exception
}
```



### 示例

```c++
#include <iostream>
using namespace std;

double division(int a, int b)
{
    if (b == 0)
    {
        throw "Division by zero condition!";
    }
    return (a/b);
}

int main()
{
    int x = 25;
    int y = 0;
    double z;
    
    try{
        z = division(x, y);
        cout << z << endl;
    }catch(const char* msg){
        cerr << msg << endl;
    }
    return 0;
}
```

- 其中`cerr`为错误的标准输出流



****

## 标准异常

- C ++提供了在`<exception>`中定义的标准异常列表 ，我们可以在程序中使用它们

![](..\images\cpp_exceptions.jpg)



| 序号 |                          异常与说明                          |
| ---- | :----------------------------------------------------------: |
| 1    |       `std :: exception`所有标准C ++异常的异常和父类。       |
| 2    |            `std :: bad_alloc`这可以由`new`抛出。             |
| 3    |        `std :: bad_cast`这可以由`dynamic_cast`抛出。         |
| 4    | `std :: bad_exception`这对于处理C ++程序中的意外异常很有用。 |
| 5    |          `std :: bad_typeid`这可以由`typeid`抛出。           |
| 6    | `std :: logic_error`从理论上讲，可以通过阅读代码来检测异常。 |
| 7    |  `std :: domain_error`使用数学上无效的域时，将引发此异常。   |
| 8    |     `std :: invalid_argument`由于参数无效而引发此错误。      |
| 9    | `std :: length_error`当创建太大的`std :: string`时抛出此错误。 |
| 10   | `std :: out_of_range`这可以通过'at'方法抛出，例如`std :: vector`和`std :: bitset <> :: operator []（）`。 |
| 11   |  `std :: runtime_error`理论上无法通过读取代码检测到的异常。  |
| 12   |  `std :: overflow_error`如果发生数学溢出，则会抛出此错误。   |
| 13   | `std :: range_error`当您尝试存储超出范围的值时，就会发生这种情况。 |
| 14   |  `std :: underflow_error`如果发生数学下溢，则会抛出此错误。  |



****

## 定义新异常

- 您可以通过继承和覆盖异常类功能来定义自己的异常

```c++
#include <iostream>
#include <exception>

using namespace std;

struct newException : public exception
{
    const char* what() const throw()
    {
        return "New Exception";
    }
};

int main()
{
    try{
		throw newException();
    }catch(newException& e){
        cout << "MyException caught" << endl;
        cout << e.what() << endl;
    }
    return 0;
}
```

